Not Found: /password_reset/
Not Found: /password_reset/
Internal Server Error: /
Traceback (most recent call last):
  File "/usr/local/lib/python3.10/site-packages/django/db/backends/base/base.py", line 279, in ensure_connection
    self.connect()
  File "/usr/local/lib/python3.10/site-packages/django/utils/asyncio.py", line 26, in inner
    return func(*args, **kwargs)
  File "/usr/local/lib/python3.10/site-packages/django/db/backends/base/base.py", line 256, in connect
    self.connection = self.get_new_connection(conn_params)
  File "/usr/local/lib/python3.10/site-packages/django/utils/asyncio.py", line 26, in inner
    return func(*args, **kwargs)
  File "/usr/local/lib/python3.10/site-packages/django/db/backends/postgresql/base.py", line 332, in get_new_connection
    connection = self.Database.connect(**conn_params)
  File "/usr/local/lib/python3.10/site-packages/psycopg2/__init__.py", line 122, in connect
    conn = _connect(dsn, connection_factory=connection_factory, **kwasync)
psycopg2.OperationalError: could not translate host name "database-1.c382m86yovsf.eu-north-1.rds.amazonaws.com" to address: Name or service not known


The above exception was the direct cause of the following exception:

Traceback (most recent call last):
  File "/usr/local/lib/python3.10/site-packages/django/core/handlers/exception.py", line 55, in inner
    response = get_response(request)
  File "/usr/local/lib/python3.10/site-packages/django/core/handlers/base.py", line 197, in _get_response
    response = wrapped_callback(request, *callback_args, **callback_kwargs)
  File "/usr/local/lib/python3.10/site-packages/django/views/generic/base.py", line 104, in view
    return self.dispatch(request, *args, **kwargs)
  File "/usr/local/lib/python3.10/site-packages/django/views/generic/base.py", line 143, in dispatch
    return handler(request, *args, **kwargs)
  File "/usr/local/lib/python3.10/site-packages/django/views/generic/list.py", line 174, in get
    context = self.get_context_data()
  File "/usr/local/lib/python3.10/site-packages/django/views/generic/list.py", line 128, in get_context_data
    paginator, page, queryset, is_paginated = self.paginate_queryset(
  File "/usr/local/lib/python3.10/site-packages/django/views/generic/list.py", line 73, in paginate_queryset
    page = paginator.page(page_number)
  File "/usr/local/lib/python3.10/site-packages/django/core/paginator.py", line 89, in page
    number = self.validate_number(number)
  File "/usr/local/lib/python3.10/site-packages/django/core/paginator.py", line 70, in validate_number
    if number > self.num_pages:
  File "/usr/local/lib/python3.10/site-packages/django/utils/functional.py", line 47, in __get__
    res = instance.__dict__[self.name] = self.func(instance)
  File "/usr/local/lib/python3.10/site-packages/django/core/paginator.py", line 116, in num_pages
    if self.count == 0 and not self.allow_empty_first_page:
  File "/usr/local/lib/python3.10/site-packages/django/utils/functional.py", line 47, in __get__
    res = instance.__dict__[self.name] = self.func(instance)
  File "/usr/local/lib/python3.10/site-packages/django/core/paginator.py", line 110, in count
    return c()
  File "/usr/local/lib/python3.10/site-packages/django/db/models/query.py", line 620, in count
    return self.query.get_count(using=self.db)
  File "/usr/local/lib/python3.10/site-packages/django/db/models/sql/query.py", line 630, in get_count
    return obj.get_aggregation(using, {"__count": Count("*")})["__count"]
  File "/usr/local/lib/python3.10/site-packages/django/db/models/sql/query.py", line 616, in get_aggregation
    result = compiler.execute_sql(SINGLE)
  File "/usr/local/lib/python3.10/site-packages/django/db/models/sql/compiler.py", line 1572, in execute_sql
    cursor = self.connection.cursor()
  File "/usr/local/lib/python3.10/site-packages/django/utils/asyncio.py", line 26, in inner
    return func(*args, **kwargs)
  File "/usr/local/lib/python3.10/site-packages/django/db/backends/base/base.py", line 320, in cursor
    return self._cursor()
  File "/usr/local/lib/python3.10/site-packages/django/db/backends/base/base.py", line 296, in _cursor
    self.ensure_connection()
  File "/usr/local/lib/python3.10/site-packages/django/utils/asyncio.py", line 26, in inner
    return func(*args, **kwargs)
  File "/usr/local/lib/python3.10/site-packages/django/db/backends/base/base.py", line 278, in ensure_connection
    with self.wrap_database_errors:
  File "/usr/local/lib/python3.10/site-packages/django/db/utils.py", line 91, in __exit__
    raise dj_exc_value.with_traceback(traceback) from exc_value
  File "/usr/local/lib/python3.10/site-packages/django/db/backends/base/base.py", line 279, in ensure_connection
    self.connect()
  File "/usr/local/lib/python3.10/site-packages/django/utils/asyncio.py", line 26, in inner
    return func(*args, **kwargs)
  File "/usr/local/lib/python3.10/site-packages/django/db/backends/base/base.py", line 256, in connect
    self.connection = self.get_new_connection(conn_params)
  File "/usr/local/lib/python3.10/site-packages/django/utils/asyncio.py", line 26, in inner
    return func(*args, **kwargs)
  File "/usr/local/lib/python3.10/site-packages/django/db/backends/postgresql/base.py", line 332, in get_new_connection
    connection = self.Database.connect(**conn_params)
  File "/usr/local/lib/python3.10/site-packages/psycopg2/__init__.py", line 122, in connect
    conn = _connect(dsn, connection_factory=connection_factory, **kwasync)
django.db.utils.OperationalError: could not translate host name "database-1.c382m86yovsf.eu-north-1.rds.amazonaws.com" to address: Name or service not known

Internal Server Error: /
Traceback (most recent call last):
  File "/usr/local/lib/python3.10/site-packages/django/db/backends/base/base.py", line 279, in ensure_connection
    self.connect()
  File "/usr/local/lib/python3.10/site-packages/django/utils/asyncio.py", line 26, in inner
    return func(*args, **kwargs)
  File "/usr/local/lib/python3.10/site-packages/django/db/backends/base/base.py", line 256, in connect
    self.connection = self.get_new_connection(conn_params)
  File "/usr/local/lib/python3.10/site-packages/django/utils/asyncio.py", line 26, in inner
    return func(*args, **kwargs)
  File "/usr/local/lib/python3.10/site-packages/django/db/backends/postgresql/base.py", line 332, in get_new_connection
    connection = self.Database.connect(**conn_params)
  File "/usr/local/lib/python3.10/site-packages/psycopg2/__init__.py", line 122, in connect
    conn = _connect(dsn, connection_factory=connection_factory, **kwasync)
psycopg2.OperationalError: could not translate host name "database-1.c382m86yovsf.eu-north-1.rds.amazonaws.com" to address: Name or service not known


The above exception was the direct cause of the following exception:

Traceback (most recent call last):
  File "/usr/local/lib/python3.10/site-packages/django/core/handlers/exception.py", line 55, in inner
    response = get_response(request)
  File "/usr/local/lib/python3.10/site-packages/django/core/handlers/base.py", line 197, in _get_response
    response = wrapped_callback(request, *callback_args, **callback_kwargs)
  File "/usr/local/lib/python3.10/site-packages/django/views/generic/base.py", line 104, in view
    return self.dispatch(request, *args, **kwargs)
  File "/usr/local/lib/python3.10/site-packages/django/views/generic/base.py", line 143, in dispatch
    return handler(request, *args, **kwargs)
  File "/usr/local/lib/python3.10/site-packages/django/views/generic/list.py", line 174, in get
    context = self.get_context_data()
  File "/usr/local/lib/python3.10/site-packages/django/views/generic/list.py", line 128, in get_context_data
    paginator, page, queryset, is_paginated = self.paginate_queryset(
  File "/usr/local/lib/python3.10/site-packages/django/views/generic/list.py", line 73, in paginate_queryset
    page = paginator.page(page_number)
  File "/usr/local/lib/python3.10/site-packages/django/core/paginator.py", line 89, in page
    number = self.validate_number(number)
  File "/usr/local/lib/python3.10/site-packages/django/core/paginator.py", line 70, in validate_number
    if number > self.num_pages:
  File "/usr/local/lib/python3.10/site-packages/django/utils/functional.py", line 47, in __get__
    res = instance.__dict__[self.name] = self.func(instance)
  File "/usr/local/lib/python3.10/site-packages/django/core/paginator.py", line 116, in num_pages
    if self.count == 0 and not self.allow_empty_first_page:
  File "/usr/local/lib/python3.10/site-packages/django/utils/functional.py", line 47, in __get__
    res = instance.__dict__[self.name] = self.func(instance)
  File "/usr/local/lib/python3.10/site-packages/django/core/paginator.py", line 110, in count
    return c()
  File "/usr/local/lib/python3.10/site-packages/django/db/models/query.py", line 620, in count
    return self.query.get_count(using=self.db)
  File "/usr/local/lib/python3.10/site-packages/django/db/models/sql/query.py", line 630, in get_count
    return obj.get_aggregation(using, {"__count": Count("*")})["__count"]
  File "/usr/local/lib/python3.10/site-packages/django/db/models/sql/query.py", line 616, in get_aggregation
    result = compiler.execute_sql(SINGLE)
  File "/usr/local/lib/python3.10/site-packages/django/db/models/sql/compiler.py", line 1572, in execute_sql
    cursor = self.connection.cursor()
  File "/usr/local/lib/python3.10/site-packages/django/utils/asyncio.py", line 26, in inner
    return func(*args, **kwargs)
  File "/usr/local/lib/python3.10/site-packages/django/db/backends/base/base.py", line 320, in cursor
    return self._cursor()
  File "/usr/local/lib/python3.10/site-packages/django/db/backends/base/base.py", line 296, in _cursor
    self.ensure_connection()
  File "/usr/local/lib/python3.10/site-packages/django/utils/asyncio.py", line 26, in inner
    return func(*args, **kwargs)
  File "/usr/local/lib/python3.10/site-packages/django/db/backends/base/base.py", line 278, in ensure_connection
    with self.wrap_database_errors:
  File "/usr/local/lib/python3.10/site-packages/django/db/utils.py", line 91, in __exit__
    raise dj_exc_value.with_traceback(traceback) from exc_value
  File "/usr/local/lib/python3.10/site-packages/django/db/backends/base/base.py", line 279, in ensure_connection
    self.connect()
  File "/usr/local/lib/python3.10/site-packages/django/utils/asyncio.py", line 26, in inner
    return func(*args, **kwargs)
  File "/usr/local/lib/python3.10/site-packages/django/db/backends/base/base.py", line 256, in connect
    self.connection = self.get_new_connection(conn_params)
  File "/usr/local/lib/python3.10/site-packages/django/utils/asyncio.py", line 26, in inner
    return func(*args, **kwargs)
  File "/usr/local/lib/python3.10/site-packages/django/db/backends/postgresql/base.py", line 332, in get_new_connection
    connection = self.Database.connect(**conn_params)
  File "/usr/local/lib/python3.10/site-packages/psycopg2/__init__.py", line 122, in connect
    conn = _connect(dsn, connection_factory=connection_factory, **kwasync)
django.db.utils.OperationalError: could not translate host name "database-1.c382m86yovsf.eu-north-1.rds.amazonaws.com" to address: Name or service not known

Internal Server Error: /
Traceback (most recent call last):
  File "/usr/local/lib/python3.10/site-packages/django/db/backends/base/base.py", line 279, in ensure_connection
    self.connect()
  File "/usr/local/lib/python3.10/site-packages/django/utils/asyncio.py", line 26, in inner
    return func(*args, **kwargs)
  File "/usr/local/lib/python3.10/site-packages/django/db/backends/base/base.py", line 256, in connect
    self.connection = self.get_new_connection(conn_params)
  File "/usr/local/lib/python3.10/site-packages/django/utils/asyncio.py", line 26, in inner
    return func(*args, **kwargs)
  File "/usr/local/lib/python3.10/site-packages/django/db/backends/postgresql/base.py", line 332, in get_new_connection
    connection = self.Database.connect(**conn_params)
  File "/usr/local/lib/python3.10/site-packages/psycopg2/__init__.py", line 122, in connect
    conn = _connect(dsn, connection_factory=connection_factory, **kwasync)
psycopg2.OperationalError: could not translate host name "database-1.c382m86yovsf.eu-north-1.rds.amazonaws.com" to address: Name or service not known


The above exception was the direct cause of the following exception:

Traceback (most recent call last):
  File "/usr/local/lib/python3.10/site-packages/django/core/handlers/exception.py", line 55, in inner
    response = get_response(request)
  File "/usr/local/lib/python3.10/site-packages/django/core/handlers/base.py", line 197, in _get_response
    response = wrapped_callback(request, *callback_args, **callback_kwargs)
  File "/usr/local/lib/python3.10/site-packages/django/views/generic/base.py", line 104, in view
    return self.dispatch(request, *args, **kwargs)
  File "/usr/local/lib/python3.10/site-packages/django/views/generic/base.py", line 143, in dispatch
    return handler(request, *args, **kwargs)
  File "/usr/local/lib/python3.10/site-packages/django/views/generic/list.py", line 174, in get
    context = self.get_context_data()
  File "/usr/local/lib/python3.10/site-packages/django/views/generic/list.py", line 128, in get_context_data
    paginator, page, queryset, is_paginated = self.paginate_queryset(
  File "/usr/local/lib/python3.10/site-packages/django/views/generic/list.py", line 73, in paginate_queryset
    page = paginator.page(page_number)
  File "/usr/local/lib/python3.10/site-packages/django/core/paginator.py", line 89, in page
    number = self.validate_number(number)
  File "/usr/local/lib/python3.10/site-packages/django/core/paginator.py", line 70, in validate_number
    if number > self.num_pages:
  File "/usr/local/lib/python3.10/site-packages/django/utils/functional.py", line 47, in __get__
    res = instance.__dict__[self.name] = self.func(instance)
  File "/usr/local/lib/python3.10/site-packages/django/core/paginator.py", line 116, in num_pages
    if self.count == 0 and not self.allow_empty_first_page:
  File "/usr/local/lib/python3.10/site-packages/django/utils/functional.py", line 47, in __get__
    res = instance.__dict__[self.name] = self.func(instance)
  File "/usr/local/lib/python3.10/site-packages/django/core/paginator.py", line 110, in count
    return c()
  File "/usr/local/lib/python3.10/site-packages/django/db/models/query.py", line 620, in count
    return self.query.get_count(using=self.db)
  File "/usr/local/lib/python3.10/site-packages/django/db/models/sql/query.py", line 630, in get_count
    return obj.get_aggregation(using, {"__count": Count("*")})["__count"]
  File "/usr/local/lib/python3.10/site-packages/django/db/models/sql/query.py", line 616, in get_aggregation
    result = compiler.execute_sql(SINGLE)
  File "/usr/local/lib/python3.10/site-packages/django/db/models/sql/compiler.py", line 1572, in execute_sql
    cursor = self.connection.cursor()
  File "/usr/local/lib/python3.10/site-packages/django/utils/asyncio.py", line 26, in inner
    return func(*args, **kwargs)
  File "/usr/local/lib/python3.10/site-packages/django/db/backends/base/base.py", line 320, in cursor
    return self._cursor()
  File "/usr/local/lib/python3.10/site-packages/django/db/backends/base/base.py", line 296, in _cursor
    self.ensure_connection()
  File "/usr/local/lib/python3.10/site-packages/django/utils/asyncio.py", line 26, in inner
    return func(*args, **kwargs)
  File "/usr/local/lib/python3.10/site-packages/django/db/backends/base/base.py", line 278, in ensure_connection
    with self.wrap_database_errors:
  File "/usr/local/lib/python3.10/site-packages/django/db/utils.py", line 91, in __exit__
    raise dj_exc_value.with_traceback(traceback) from exc_value
  File "/usr/local/lib/python3.10/site-packages/django/db/backends/base/base.py", line 279, in ensure_connection
    self.connect()
  File "/usr/local/lib/python3.10/site-packages/django/utils/asyncio.py", line 26, in inner
    return func(*args, **kwargs)
  File "/usr/local/lib/python3.10/site-packages/django/db/backends/base/base.py", line 256, in connect
    self.connection = self.get_new_connection(conn_params)
  File "/usr/local/lib/python3.10/site-packages/django/utils/asyncio.py", line 26, in inner
    return func(*args, **kwargs)
  File "/usr/local/lib/python3.10/site-packages/django/db/backends/postgresql/base.py", line 332, in get_new_connection
    connection = self.Database.connect(**conn_params)
  File "/usr/local/lib/python3.10/site-packages/psycopg2/__init__.py", line 122, in connect
    conn = _connect(dsn, connection_factory=connection_factory, **kwasync)
django.db.utils.OperationalError: could not translate host name "database-1.c382m86yovsf.eu-north-1.rds.amazonaws.com" to address: Name or service not known

Internal Server Error: /
Traceback (most recent call last):
  File "/usr/local/lib/python3.10/site-packages/django/db/backends/base/base.py", line 279, in ensure_connection
    self.connect()
  File "/usr/local/lib/python3.10/site-packages/django/utils/asyncio.py", line 26, in inner
    return func(*args, **kwargs)
  File "/usr/local/lib/python3.10/site-packages/django/db/backends/base/base.py", line 256, in connect
    self.connection = self.get_new_connection(conn_params)
  File "/usr/local/lib/python3.10/site-packages/django/utils/asyncio.py", line 26, in inner
    return func(*args, **kwargs)
  File "/usr/local/lib/python3.10/site-packages/django/db/backends/postgresql/base.py", line 332, in get_new_connection
    connection = self.Database.connect(**conn_params)
  File "/usr/local/lib/python3.10/site-packages/psycopg2/__init__.py", line 122, in connect
    conn = _connect(dsn, connection_factory=connection_factory, **kwasync)
psycopg2.OperationalError: could not translate host name "database-1.c382m86yovsf.eu-north-1.rds.amazonaws.com" to address: Temporary failure in name resolution


The above exception was the direct cause of the following exception:

Traceback (most recent call last):
  File "/usr/local/lib/python3.10/site-packages/django/core/handlers/exception.py", line 55, in inner
    response = get_response(request)
  File "/usr/local/lib/python3.10/site-packages/django/core/handlers/base.py", line 197, in _get_response
    response = wrapped_callback(request, *callback_args, **callback_kwargs)
  File "/usr/local/lib/python3.10/site-packages/django/views/generic/base.py", line 104, in view
    return self.dispatch(request, *args, **kwargs)
  File "/usr/local/lib/python3.10/site-packages/django/views/generic/base.py", line 143, in dispatch
    return handler(request, *args, **kwargs)
  File "/usr/local/lib/python3.10/site-packages/django/views/generic/list.py", line 174, in get
    context = self.get_context_data()
  File "/usr/local/lib/python3.10/site-packages/django/views/generic/list.py", line 128, in get_context_data
    paginator, page, queryset, is_paginated = self.paginate_queryset(
  File "/usr/local/lib/python3.10/site-packages/django/views/generic/list.py", line 73, in paginate_queryset
    page = paginator.page(page_number)
  File "/usr/local/lib/python3.10/site-packages/django/core/paginator.py", line 89, in page
    number = self.validate_number(number)
  File "/usr/local/lib/python3.10/site-packages/django/core/paginator.py", line 70, in validate_number
    if number > self.num_pages:
  File "/usr/local/lib/python3.10/site-packages/django/utils/functional.py", line 47, in __get__
    res = instance.__dict__[self.name] = self.func(instance)
  File "/usr/local/lib/python3.10/site-packages/django/core/paginator.py", line 116, in num_pages
    if self.count == 0 and not self.allow_empty_first_page:
  File "/usr/local/lib/python3.10/site-packages/django/utils/functional.py", line 47, in __get__
    res = instance.__dict__[self.name] = self.func(instance)
  File "/usr/local/lib/python3.10/site-packages/django/core/paginator.py", line 110, in count
    return c()
  File "/usr/local/lib/python3.10/site-packages/django/db/models/query.py", line 620, in count
    return self.query.get_count(using=self.db)
  File "/usr/local/lib/python3.10/site-packages/django/db/models/sql/query.py", line 630, in get_count
    return obj.get_aggregation(using, {"__count": Count("*")})["__count"]
  File "/usr/local/lib/python3.10/site-packages/django/db/models/sql/query.py", line 616, in get_aggregation
    result = compiler.execute_sql(SINGLE)
  File "/usr/local/lib/python3.10/site-packages/django/db/models/sql/compiler.py", line 1572, in execute_sql
    cursor = self.connection.cursor()
  File "/usr/local/lib/python3.10/site-packages/django/utils/asyncio.py", line 26, in inner
    return func(*args, **kwargs)
  File "/usr/local/lib/python3.10/site-packages/django/db/backends/base/base.py", line 320, in cursor
    return self._cursor()
  File "/usr/local/lib/python3.10/site-packages/django/db/backends/base/base.py", line 296, in _cursor
    self.ensure_connection()
  File "/usr/local/lib/python3.10/site-packages/django/utils/asyncio.py", line 26, in inner
    return func(*args, **kwargs)
  File "/usr/local/lib/python3.10/site-packages/django/db/backends/base/base.py", line 278, in ensure_connection
    with self.wrap_database_errors:
  File "/usr/local/lib/python3.10/site-packages/django/db/utils.py", line 91, in __exit__
    raise dj_exc_value.with_traceback(traceback) from exc_value
  File "/usr/local/lib/python3.10/site-packages/django/db/backends/base/base.py", line 279, in ensure_connection
    self.connect()
  File "/usr/local/lib/python3.10/site-packages/django/utils/asyncio.py", line 26, in inner
    return func(*args, **kwargs)
  File "/usr/local/lib/python3.10/site-packages/django/db/backends/base/base.py", line 256, in connect
    self.connection = self.get_new_connection(conn_params)
  File "/usr/local/lib/python3.10/site-packages/django/utils/asyncio.py", line 26, in inner
    return func(*args, **kwargs)
  File "/usr/local/lib/python3.10/site-packages/django/db/backends/postgresql/base.py", line 332, in get_new_connection
    connection = self.Database.connect(**conn_params)
  File "/usr/local/lib/python3.10/site-packages/psycopg2/__init__.py", line 122, in connect
    conn = _connect(dsn, connection_factory=connection_factory, **kwasync)
django.db.utils.OperationalError: could not translate host name "database-1.c382m86yovsf.eu-north-1.rds.amazonaws.com" to address: Temporary failure in name resolution

Not Found: /media/profile_pics/unnamed_SVmgNqb.jpg
Not Found: /media/profile_pics/unnamed_SVmgNqb.jpg
Not Found: /favicon.ico
Not Found: /media/profile_pics/unnamed_SVmgNqb.jpg
Not Found: /media/profile_pics/unnamed_SVmgNqb.jpg
Not Found: /media/profile_pics/unnamed_SVmgNqb.jpg
Not Found: /password_reset/
Not Found: /media/profile_pics/unnamed_SVmgNqb.jpg
Not Found: /media/profile_pics/unnamed_SVmgNqb.jpg
Not Found: /media/profile_pics/unnamed_SVmgNqb.jpg
Not Found: /media/profile_pics/unnamed_SVmgNqb.jpg
Not Found: /media/profile_pics/unnamed_SVmgNqb.jpg
Not Found: /media/profile_pics/unnamed_wqnC3JB.jpg
Not Found: /media/profile_pics/unnamed_wqnC3JB.jpg
Not Found: /media/profile_pics/unnamed_wqnC3JB.jpg
Not Found: /media/profile_pics/unnamed_wqnC3JB.jpg
Not Found: /media/profile_pics/unnamed_wqnC3JB.jpg
Not Found: /media/profile_pics/default.jpg
Not Found: /media/profile_pics/default.jpg
Not Found: /media/profile_pics/default.jpg
Not Found: /media/profile_pics/default.jpg
Not Found: /media/profile_pics/default.jpg
Not Found: /media/profile_pics/default.jpg
Not Found: /media/profile_pics/default.jpg
Not Found: /media/profile_pics/default.jpg
Not Found: /media/profile_pics/default.jpg
Not Found: /media/profile_pics/default.jpg
Not Found: /media/profile_pics/default.jpg
Not Found: /media/profile_pics/unnamed_AfRvFgY.jpg
Not Found: /media/profile_pics/unnamed_AfRvFgY.jpg
Not Found: /favicon.ico
Not Found: /media/profile_pics/unnamed_AfRvFgY.jpg
Not Found: /media/profile_pics/unnamed_AfRvFgY.jpg
Not Found: /media/profile_pics/unnamed_vTA9oHK.jpg
Not Found: /media/profile_pics/unnamed_vTA9oHK.jpg
Not Found: /media/profile_pics/unnamed_vTA9oHK.jpg
Not Found: /media/profile_pics/unnamed_vTA9oHK.jpg
Not Found: /media/profile_pics/unnamed_vTA9oHK.jpg
Not Found: /media/profile_pics/unnamed_vTA9oHK.jpg
Not Found: /media/profile_pics/unnamed_CMaQzRL.jpg
Not Found: /media/profile_pics/unnamed_CMaQzRL.jpg
Not Found: /media/profile_pics/unnamed_CMaQzRL.jpg
Not Found: /media/profile_pics/unnamed_CMaQzRL.jpg
Not Found: /media/default.jpg
Not Found: /media/profile_pics/unnamed_CMaQzRL.jpg
Not Found: /media/default.jpg
Not Found: /media/default.jpg
Not Found: /media/profile_pics/unnamed_CMaQzRL.jpg
Not Found: /media/profile_pics/unnamed_CMaQzRL.jpg
Not Found: /media/default.jpg
Not Found: /media/default.jpg
Not Found: /media/profile_pics/unnamed_CMaQzRL.jpg
Not Found: /media/profile_pics/unnamed_CMaQzRL.jpg
Not Found: /media/default.jpg
Not Found: /media/profile_pics/unnamed_CMaQzRL.jpg
Not Found: /media/default.jpg
Not Found: /media/default.jpg
Not Found: /media/profile_pics/unnamed_CMaQzRL.jpg
Internal Server Error: /
Traceback (most recent call last):
  File "/usr/local/lib/python3.10/site-packages/django/db/backends/base/base.py", line 279, in ensure_connection
    self.connect()
  File "/usr/local/lib/python3.10/site-packages/django/utils/asyncio.py", line 26, in inner
    return func(*args, **kwargs)
  File "/usr/local/lib/python3.10/site-packages/django/db/backends/base/base.py", line 256, in connect
    self.connection = self.get_new_connection(conn_params)
  File "/usr/local/lib/python3.10/site-packages/django/utils/asyncio.py", line 26, in inner
    return func(*args, **kwargs)
  File "/usr/local/lib/python3.10/site-packages/django/db/backends/postgresql/base.py", line 332, in get_new_connection
    connection = self.Database.connect(**conn_params)
  File "/usr/local/lib/python3.10/site-packages/psycopg2/__init__.py", line 122, in connect
    conn = _connect(dsn, connection_factory=connection_factory, **kwasync)
psycopg2.OperationalError: could not translate host name "database-1.c382m86yovsf.eu-north-1.rds.amazonaws.com" to address: Temporary failure in name resolution


The above exception was the direct cause of the following exception:

Traceback (most recent call last):
  File "/usr/local/lib/python3.10/site-packages/django/core/handlers/exception.py", line 55, in inner
    response = get_response(request)
  File "/usr/local/lib/python3.10/site-packages/django/core/handlers/base.py", line 197, in _get_response
    response = wrapped_callback(request, *callback_args, **callback_kwargs)
  File "/usr/local/lib/python3.10/site-packages/django/views/generic/base.py", line 104, in view
    return self.dispatch(request, *args, **kwargs)
  File "/usr/local/lib/python3.10/site-packages/django/views/generic/base.py", line 143, in dispatch
    return handler(request, *args, **kwargs)
  File "/usr/local/lib/python3.10/site-packages/django/views/generic/list.py", line 174, in get
    context = self.get_context_data()
  File "/usr/local/lib/python3.10/site-packages/django/views/generic/list.py", line 128, in get_context_data
    paginator, page, queryset, is_paginated = self.paginate_queryset(
  File "/usr/local/lib/python3.10/site-packages/django/views/generic/list.py", line 73, in paginate_queryset
    page = paginator.page(page_number)
  File "/usr/local/lib/python3.10/site-packages/django/core/paginator.py", line 89, in page
    number = self.validate_number(number)
  File "/usr/local/lib/python3.10/site-packages/django/core/paginator.py", line 70, in validate_number
    if number > self.num_pages:
  File "/usr/local/lib/python3.10/site-packages/django/utils/functional.py", line 47, in __get__
    res = instance.__dict__[self.name] = self.func(instance)
  File "/usr/local/lib/python3.10/site-packages/django/core/paginator.py", line 116, in num_pages
    if self.count == 0 and not self.allow_empty_first_page:
  File "/usr/local/lib/python3.10/site-packages/django/utils/functional.py", line 47, in __get__
    res = instance.__dict__[self.name] = self.func(instance)
  File "/usr/local/lib/python3.10/site-packages/django/core/paginator.py", line 110, in count
    return c()
  File "/usr/local/lib/python3.10/site-packages/django/db/models/query.py", line 620, in count
    return self.query.get_count(using=self.db)
  File "/usr/local/lib/python3.10/site-packages/django/db/models/sql/query.py", line 630, in get_count
    return obj.get_aggregation(using, {"__count": Count("*")})["__count"]
  File "/usr/local/lib/python3.10/site-packages/django/db/models/sql/query.py", line 616, in get_aggregation
    result = compiler.execute_sql(SINGLE)
  File "/usr/local/lib/python3.10/site-packages/django/db/models/sql/compiler.py", line 1572, in execute_sql
    cursor = self.connection.cursor()
  File "/usr/local/lib/python3.10/site-packages/django/utils/asyncio.py", line 26, in inner
    return func(*args, **kwargs)
  File "/usr/local/lib/python3.10/site-packages/django/db/backends/base/base.py", line 320, in cursor
    return self._cursor()
  File "/usr/local/lib/python3.10/site-packages/django/db/backends/base/base.py", line 296, in _cursor
    self.ensure_connection()
  File "/usr/local/lib/python3.10/site-packages/django/utils/asyncio.py", line 26, in inner
    return func(*args, **kwargs)
  File "/usr/local/lib/python3.10/site-packages/django/db/backends/base/base.py", line 278, in ensure_connection
    with self.wrap_database_errors:
  File "/usr/local/lib/python3.10/site-packages/django/db/utils.py", line 91, in __exit__
    raise dj_exc_value.with_traceback(traceback) from exc_value
  File "/usr/local/lib/python3.10/site-packages/django/db/backends/base/base.py", line 279, in ensure_connection
    self.connect()
  File "/usr/local/lib/python3.10/site-packages/django/utils/asyncio.py", line 26, in inner
    return func(*args, **kwargs)
  File "/usr/local/lib/python3.10/site-packages/django/db/backends/base/base.py", line 256, in connect
    self.connection = self.get_new_connection(conn_params)
  File "/usr/local/lib/python3.10/site-packages/django/utils/asyncio.py", line 26, in inner
    return func(*args, **kwargs)
  File "/usr/local/lib/python3.10/site-packages/django/db/backends/postgresql/base.py", line 332, in get_new_connection
    connection = self.Database.connect(**conn_params)
  File "/usr/local/lib/python3.10/site-packages/psycopg2/__init__.py", line 122, in connect
    conn = _connect(dsn, connection_factory=connection_factory, **kwasync)
django.db.utils.OperationalError: could not translate host name "database-1.c382m86yovsf.eu-north-1.rds.amazonaws.com" to address: Temporary failure in name resolution

